#VRML_SIM R2023b utf8

EXTERNPROTO "https://raw.githubusercontent.com/cyberbotics/webots/R2023b/projects/objects/floors/protos/Floor.proto"
EXTERNPROTO "https://raw.githubusercontent.com/cyberbotics/webots/R2023b/projects/objects/backgrounds/protos/TexturedBackground.proto"
EXTERNPROTO "https://raw.githubusercontent.com/cyberbotics/webots/R2023b/projects/objects/backgrounds/protos/TexturedBackgroundLight.proto"

WorldInfo {
}
Viewpoint {
  orientation 0.5315897106254144 0.5602866693470838 -0.6352095935273172 1.9630300799786107
  position -0.08007082919095732 1.6278471875738898 5.788870248683336
}
TexturedBackground {
}
TexturedBackgroundLight {
}
DEF Floor Floor {
  translation 0 0 -0.07
  size 4 4
  tileSize 0.4 0.4
}
DEF Walls Group {
  children [
    DEF Wall Solid {
      translation 0.982729 0.209349 4.26396e-07
      rotation -0.8628556898685809 -0.357406871539237 -0.3574078715388776 -1.7177753071795863
      children [
        DEF Wall Shape {
          appearance PBRAppearance {
            baseColor 0.392157 0.392157 0.392157
            roughness 1
            metalness 0
          }
          geometry Box {
            size 1.2 0.15 0.015
          }
        }
      ]
      name "solid(6)"
      boundingObject USE Wall
    }
    DEF Wall Solid {
      translation -0.9898 0.21642 -4.32902e-07
      rotation 0.8628559982596194 -0.35740699927911007 0.35740699927911007 -1.7177753071795863
      children [
        DEF Wall Shape {
          appearance PBRAppearance {
            baseColor 0.392157 0.392157 0.392157
            roughness 1
            metalness 0
          }
          geometry Box {
            size 1.2 0.15 0.015
          }
        }
      ]
      name "solid(9)"
      boundingObject USE Wall
    }
    DEF Wall Solid {
      translation 0.982725 1.05787 -2.76289e-06
      rotation 0.2810839910810645 0.6785989784677153 0.6785979784677472 2.59356
      children [
        DEF Wall Shape {
          appearance PBRAppearance {
            baseColor 0.392157 0.392157 0.392157
            roughness 1
            metalness 0
          }
          geometry Box {
            size 1.2 0.15 0.015
          }
        }
      ]
      name "solid(5)"
      boundingObject USE Wall
    }
    DEF Wall Solid {
      translation -0.975658 1.0508 -1.47264e-06
      rotation 0.8628559982596194 0.35740699927911007 0.35740699927911007 1.71777
      children [
        DEF Wall Shape {
          appearance PBRAppearance {
            baseColor 0.392157 0.392157 0.392157
            roughness 1
            metalness 0
          }
          geometry Box {
            size 1.2 0.15 0.015
          }
        }
      ]
      name "solid(8)"
      boundingObject USE Wall
    }
    DEF Wall Solid {
      translation 0.282801 1.20634 -1.71775e-06
      rotation 0.8628559982596194 0.35740699927911007 0.35740699927911007 1.71777
      children [
        DEF Wall Shape {
          appearance PBRAppearance {
            baseColor 0.392157 0.392157 0.392157
            roughness 1
            metalness 0
          }
          geometry Box {
            size 0.8 0.15 0.015
          }
        }
      ]
      name "solid(7)"
      boundingObject USE Wall
    }
    DEF Wall Solid {
      translation -0.2828 0.075 0
      rotation 0.8628559982596194 0.35740699927911007 0.35740699927911007 1.71777
      children [
        DEF Wall Shape {
          appearance PBRAppearance {
            baseColor 0.392157 0.392157 0.392157
            roughness 1
            metalness 0
          }
          geometry Box {
            size 0.8 0.15 0.015
          }
        }
      ]
      name "solid(10)"
      boundingObject USE Wall
    }
    DEF Wall Solid {
      translation -0.275729 1.1993 -3.4505e-06
      rotation 0.8628559982596194 -0.35740699927911007 0.35740699927911007 -1.7177753071795863
      children [
        DEF Wall Shape {
          appearance PBRAppearance {
            baseColor 0.392157 0.392157 0.392157
            roughness 1
            metalness 0
          }
          geometry Box {
            size 0.8 0.15 0.015
          }
        }
      ]
      name "solid(16)"
      boundingObject USE Wall
    }
    DEF Wall Solid {
      translation 0.2828 0.075 0
      rotation 0.8628559982596194 -0.35740699927911007 0.35740699927911007 -1.7177753071795863
      children [
        DEF Wall Shape {
          appearance PBRAppearance {
            baseColor 0.392157 0.392157 0.392157
            roughness 1
            metalness 0
          }
          geometry Box {
            size 0.8 0.15 0.015
          }
        }
      ]
      name "solid(19)"
      boundingObject USE Wall
    }
    DEF Wall Solid {
      translation 0.749426 0.527546 -6.60411e-07
      rotation 0.8628559982596194 0.35740699927911007 0.35740699927911007 1.71777
      children [
        DEF Wall Shape {
          appearance PBRAppearance {
            baseColor 0.392157 0.392157 0.392157
            roughness 1
            metalness 0
          }
          geometry Box {
            size 0.4 0.15 0.015
          }
        }
      ]
      name "solid(2)"
      boundingObject USE Wall
    }
    DEF Wall Solid {
      translation -0.706999 0.796246 -1.09504e-06
      rotation 0.8628559982596194 0.35740699927911007 0.35740699927911007 1.71777
      children [
        DEF Wall Shape {
          appearance PBRAppearance {
            baseColor 0.392157 0.392157 0.392157
            roughness 1
            metalness 0
          }
          geometry Box {
            size 0.4 0.15 0.015
          }
        }
      ]
      name "solid(13)"
      boundingObject USE Wall
    }
    DEF Wall Solid {
      translation 0.4737 0.803317 -4.63915e-07
      rotation 0.8628568705192763 0.357405946367489 0.357405946367489 1.71777
      children [
        DEF Wall Shape {
          appearance PBRAppearance {
            baseColor 0.392157 0.392157 0.392157
            roughness 1
            metalness 0
          }
          geometry Box {
            size 0.4 0.15 0.015
          }
        }
      ]
      name "solid(4)"
      boundingObject USE Wall
    }
    DEF Wall Solid {
      translation -0.417128 0.520475 -6.7191e-07
      rotation 0.8628559982596194 0.35740699927911007 0.35740699927911007 1.71777
      children [
        DEF Wall Shape {
          appearance PBRAppearance {
            baseColor 0.392157 0.392157 0.392157
            roughness 1
            metalness 0
          }
          geometry Box {
            size 0.4 0.15 0.015
          }
        }
      ]
      name "solid(11)"
      boundingObject USE Wall
    }
    DEF Wall Solid {
      translation 0.756491 0.803317 1.13276e-07
      rotation 0.8628583595540164 -0.357405148931114 -0.3574031489302807 1.71777
      children [
        DEF Wall Shape {
          appearance PBRAppearance {
            baseColor 0.392157 0.392157 0.392157
            roughness 1
            metalness 0
          }
          geometry Box {
            size 0.4 0.15 0.015
          }
        }
      ]
      name "solid(3)"
      boundingObject USE Wall
    }
    DEF Wall Solid {
      translation -0.707003 0.513406 2.7086e-07
      rotation 0.28108287934646486 0.6785987087146205 -0.6785987087146205 -2.593565307179586
      children [
        DEF Wall Shape {
          appearance PBRAppearance {
            baseColor 0.392157 0.392157 0.392157
            roughness 1
            metalness 0
          }
          geometry Box {
            size 0.4 0.15 0.015
          }
        }
      ]
      name "solid(12)"
      boundingObject USE Wall
    }
    DEF Wall Solid {
      translation 0.473494 0.520476 7.2177e-08
      rotation 0.2810819583540569 0.6785988994567587 0.6785988994567587 2.59357
      children [
        DEF Wall Shape {
          appearance PBRAppearance {
            baseColor 0.392157 0.392157 0.392157
            roughness 1
            metalness 0
          }
          geometry Box {
            size 0.4 0.15 0.015
          }
        }
      ]
      name "solid(17)"
      boundingObject USE Wall
    }
    DEF Wall Solid {
      translation -0.424203 0.796246 4.45613e-07
      rotation 0.28108287934646486 0.6785987087146205 -0.6785987087146205 -2.593565307179586
      children [
        DEF Wall Shape {
          appearance PBRAppearance {
            baseColor 0.392157 0.392157 0.392157
            roughness 1
            metalness 0
          }
          geometry Box {
            size 0.4 0.15 0.015
          }
        }
      ]
      name "solid(20)"
      boundingObject USE Wall
    }
  ]
}
DEF ROBOT_RED Robot {
  translation -0.941281 0.887463 -0.049996
  rotation -0.7745972141161279 0.44721112361923393 0.44721512362033955 -1.823475307179586
  children [
    Compass {
    }
    GPS {
    }
    Gyro {
    }
    Accelerometer {
    }
    Lidar {
      rotation -0.5773502691896258 0.5773502691896258 0.5773502691896258 2.0943951023931957
    }
    DEF MAIN_BODY Pose {
      translation 0 0.0415 0
      rotation -1 0 0 1.5707963267948966
      children [
        Shape {
          appearance PBRAppearance {
            baseColor 0.196078 0.196078 0.196078
            roughness 1
            metalness 0
          }
          geometry DEF BODY Cylinder {
            height 0.08
            radius 0.045
          }
        }
      ]
    }
    DEF LEFT_WHEEL HingeJoint {
      jointParameters HingeJointParameters {
        position 716.4543820994643
        axis -1 0 0
        anchor 0 0.025 0
      }
      device [
        RotationalMotor {
          name "left wheel motor"
        }
      ]
      endPoint DEF LEFT_WHEEL Solid {
        translation -0.029999999999992692 0.025 0
        rotation 1 0 0 4.8134129190086
        children [
          DEF WHEEL Pose {
            rotation -0.5776567755050862 -0.5771969549958951 0.5771969549958951 2.0939354039397986
            children [
              Shape {
                appearance PBRAppearance {
                  baseColor 0.196078 0.196078 0.196078
                  roughness 1
                  metalness 0
                }
                geometry Cylinder {
                  height 0.01
                  radius 0.025
                }
              }
            ]
          }
        ]
        name "left wheel"
        boundingObject DEF WHEEL Pose {
          rotation -0.5776567755050862 -0.5771969549958951 0.5771969549958951 2.0939354039397986
          children [
            Shape {
              appearance PBRAppearance {
                baseColor 0 0 1
                roughness 1
                metalness 0
              }
              geometry Cylinder {
                height 0.01
                radius 0.025
              }
            }
          ]
        }
        physics DEF PHYSICS_WHEEL Physics {
          density -1
          mass 0.05
        }
      }
    }
    DEF RIGHT_WHEEL HingeJoint {
      jointParameters HingeJointParameters {
        position -20.216961239977245
        axis -1 0 0
        anchor 0 0.025 0
      }
      device [
        RotationalMotor {
          name "right wheel motor"
        }
      ]
      endPoint DEF RIGHT_WHEEL Solid {
        translation 0.02999999999999981 0.025 0
        rotation -1 0 0 0.32842998874106355
        children [
          DEF WHEEL Pose {
            rotation -0.5776567755050862 -0.5771969549958951 0.5771969549958951 2.0939354039397986
            children [
              Shape {
                appearance PBRAppearance {
                  baseColor 0.196078 0.196078 0.196078
                  roughness 1
                  metalness 0
                }
                geometry Cylinder {
                  height 0.01
                  radius 0.025
                }
              }
            ]
          }
        ]
        name "right wheel"
        boundingObject USE WHEEL
        physics DEF PHYSICS_WHEEL Physics {
          density -1
          mass 0.05
        }
      }
    }
    DEF DS0 DistanceSensor {
      translation 0.045 0.063 0
      children [
        DEF INFRARED Pose {
          rotation -0.5776567755050862 -0.5771969549958951 0.5771969549958951 2.0939354039397986
          children [
            Shape {
              appearance PBRAppearance {
                baseColor 0.975691 0.981481 0.0252992
                roughness 1
                metalness 0
              }
              geometry Cylinder {
                height 0.004
                radius 0.008
              }
            }
          ]
        }
      ]
      name "ds0"
      lookupTable [
        0 1000 0
        0.01 1000 0.01
        0.1 500 0.01
        0.9 50 0.01
        1 10 0
      ]
      aperture 1
    }
    DEF DS1 DistanceSensor {
      translation 0.0225 0.063 -0.039
      rotation 0 1 0 1.0472003061004251
      children [
        DEF INFRARED Pose {
          rotation -0.5776567755050862 -0.5771969549958951 0.5771969549958951 2.0939354039397986
          children [
            Shape {
              appearance PBRAppearance {
                baseColor 0.975691 0.981481 0.0252992
                roughness 1
                metalness 0
              }
              geometry Cylinder {
                height 0.004
                radius 0.008
              }
            }
          ]
        }
      ]
      name "ds1"
      lookupTable [
        0 1000 0
        0.01 1000 0.01
        0.1 500 0.01
        0.9 50 0.01
        1 10 0
      ]
      aperture 1
    }
    DEF DS6 DistanceSensor {
      translation 0 0.063 -0.044
      rotation 0 1 0 1.5707903061004251
      children [
        DEF INFRARED Pose {
          rotation -0.5776567755050862 -0.5771969549958951 0.5771969549958951 2.0939354039397986
          children [
            Shape {
              appearance PBRAppearance {
                baseColor 0.975691 0.981481 0.0252992
                roughness 1
                metalness 0
              }
              geometry Cylinder {
                height 0.004
                radius 0.008
              }
            }
          ]
        }
      ]
      name "ds6"
      lookupTable [
        0 1000 0
        0.01 1000 0.01
        0.1 500 0.01
        0.9 50 0.01
        1 10 0
      ]
      aperture 1
    }
    DEF DS4 DistanceSensor {
      translation 0.039 0.063 -0.0233
      rotation 0 -1 0 -0.5236053071795865
      children [
        DEF INFRARED Pose {
          rotation -0.5776567755050862 -0.5771969549958951 0.5771969549958951 2.0939354039397986
          children [
            Shape {
              appearance PBRAppearance {
                baseColor 0.975691 0.981481 0.0252992
                roughness 1
                metalness 0
              }
              geometry Cylinder {
                height 0.004
                radius 0.008
              }
            }
          ]
        }
      ]
      name "ds4"
      lookupTable [
        0 1000 0
        0.01 1000 0.01
        0.1 500 0.01
        0.9 50 0.01
        1 10 0
      ]
      aperture 1
    }
    DEF DS2 DistanceSensor {
      translation -0.0225 0.063 -0.039
      rotation 0 1 0 2.094399693899575
      children [
        DEF INFRARED Pose {
          rotation -0.5776567755050862 -0.5771969549958951 0.5771969549958951 2.0939354039397986
          children [
            Shape {
              appearance PBRAppearance {
                baseColor 0.975691 0.981481 0.0252992
                roughness 1
                metalness 0
              }
              geometry Cylinder {
                height 0.004
                radius 0.008
              }
            }
          ]
        }
      ]
      name "ds2"
      lookupTable [
        0 1000 0
        0.01 1000 0.01
        0.1 500 0.01
        0.9 50 0.01
        1 10 0
      ]
      aperture 1
    }
    DEF DS3 DistanceSensor {
      translation -0.045 0.063 0
      rotation 0 1 0 3.141592653589793
      children [
        DEF INFRARED Pose {
          rotation -0.5776567755050862 -0.5771969549958951 0.5771969549958951 2.0939354039397986
          children [
            Shape {
              appearance PBRAppearance {
                baseColor 0.975691 0.981481 0.0252992
                roughness 1
                metalness 0
              }
              geometry Cylinder {
                height 0.004
                radius 0.008
              }
            }
          ]
        }
      ]
      name "ds3"
      lookupTable [
        0 1000 0
        0.01 1000 0.01
        0.1 500 0.01
        0.9 50 0.01
        1 10 0
      ]
      aperture 1
    }
    DEF DS5 DistanceSensor {
      translation -0.039 0.063 -0.022
      rotation 0 -1 0 -2.6179953071795863
      children [
        DEF INFRARED Pose {
          rotation -0.5776567755050862 -0.5771969549958951 0.5771969549958951 2.0939354039397986
          children [
            Shape {
              appearance PBRAppearance {
                baseColor 0.975691 0.981481 0.0252992
                roughness 1
                metalness 0
              }
              geometry Cylinder {
                height 0.004
                radius 0.008
              }
            }
          ]
        }
      ]
      name "ds5"
      lookupTable [
        0 1000 0
        0.01 1000 0.01
        0.1 500 0.01
        0.9 50 0.01
        1 10 0
      ]
      aperture 1
    }
    DEF LED LED {
      translation 0 0.08 0
      children [
        Group {
          children [
            Shape {
              appearance PBRAppearance {
                baseColor 1 0 0
                roughness 1
                metalness 0
              }
              geometry DEF LED_SHAPE Sphere {
                radius 0.01
              }
            }
            PointLight {
              attenuation 0 0 1
              color 0 0 0
              intensity 0.5
              location 0 0.03 0
              on FALSE
              castShadows TRUE
            }
          ]
        }
      ]
      color [
        1 0 0
        0 1 0
        0 0 1
        1 1 0
        0 1 1
        1 0 1
        1 0.647059 0
        0.627451 0.12549 0.941176
        0.545098 0.411765 0.0784314
      ]
    }
  ]
  name "ROBOT_RED"
  boundingObject DEF MYBOT_BOUNDING Pose {
    translation 0 0.0415 0
    rotation -1 0 0 1.5707963267948966
    children [
      DEF BODY Cylinder {
        height 0.08
        radius 0.045
      }
    ]
  }
  physics DEF MYBOT_PHYSICS Physics {
    density -1
    mass 0.5
  }
  controller "nmp_controller_python"
}
